<?xml version="1.0"?>
<robot xmlns:xacro="http://www.ros.org/wiki/xacro"  name="robot">

    <xacro:include filename="inertial_macros.xacro"/>


    <material name="white">
        <color rgba='1 1 1 1' />
    </material>

    <material name="orange">
        <color rgba='1 0.3 0.1 1' />
    </material>
    <material name="blue">
        <color rgba='0.2 0.2 1 1' />
    </material>
    <material name="black">
        <color rgba='0 0 0 1' />
    </material>
    <material name="red">
        <color rgba='1 0 0 1' />
    </material>

    <!--BASE LINK-->


    <link name="base_link">
    </link>

    <joint name="base_footprint_joint" type="fixed">
        <parent link="base_link"/>
        <child link="base_footprint"/>
        <origin xyz="0 0 0" rpy="0 0 0"/>
    </joint>

    <link name="base_footprint">

    </link>

    <!--CHASSIS LINK-->


    <joint name="chassis_joint" type="fixed">
        <parent link="base_link"/>
        <child link="chassis"/>
        <origin xyz="-0.125 0 0"/>
    </joint>

    <link name="chassis">
        <visual>
            <origin xyz="0.125 0 0.05"/>
            <geometry>
                <box size="0.25 0.2 0.1"/>
            </geometry>
            <material name="white"/>    
        </visual>
        <collision>
            <origin xyz="0.125 0 0.05"/>
            <geometry>
                <box size="0.25 0.2 0.1"/>
            </geometry>
        </collision>
        <xacro:inertial_box mass="0.5" x="0.25" y="0.2" z="0.1" >
            <origin xyz="0.125 0 0.05" rpy="0 0 0"/>
        </xacro:inertial_box>
    </link>

    <gazebo reference="chassis">
        <material>Gazebo/White</material>
    </gazebo>

    <!--LEFT WHEEL LINK-->


    <joint name="left_front" type="continuous">
        <parent link="base_link"/>
        <child link="left_wheel_front"/>
        <origin xyz="0.0625 0.11 0" rpy="-${pi/2} 0 0"/>
        <axis xyz="0 0 1"/>
    </joint>    
    <link name="left_wheel_front">
        <visual>
            <geometry>
                <cylinder radius="0.05" length="0.02"/>
            </geometry>
            <material name="blue"/>
        </visual>
        <collision>
            <geometry>
                <cylinder radius="0.05" length="0.02"/>
            </geometry>
        </collision>
        <xacro:inertial_cylinder mass="0.1" length="0.02" radius="0.05">
            <origin xyz="0 0 0" rpy="0 0 0"/>
        </xacro:inertial_cylinder>
    </link>

    <gazebo reference="left_wheel_front">
        <material>Gazebo/Blue</material>
    </gazebo>

    <joint name="left_rear" type="continuous">
        <parent link="base_link"/>
        <child link="left_wheel_rear"/>
        <origin xyz="-0.0625 0.11 0" rpy="-${pi/2} 0 0"/>
        <axis xyz="0 0 1"/>
    </joint>
    <link name="left_wheel_rear">
        <visual>
            <geometry>
                <cylinder radius="0.05" length="0.02"/>
            </geometry>
            <material name="black"/>
        </visual>
        <collision>
            <geometry>
                <cylinder radius="0.05" length="0.02"/>
            </geometry>
        </collision>
        <xacro:inertial_cylinder mass="0.1" length="0.02" radius="0.05">
            <origin xyz="0 0 0" rpy="0 0 0"/>
        </xacro:inertial_cylinder>
    </link>

    <gazebo reference="left_wheel_rear">
        <material>Gazebo/Black</material>
    </gazebo>


    <!--RIGHT WHEEL LINK-->


    <joint name="right_front" type="continuous">
        <parent link="base_link"/>
        <child link="right_wheel_front"/>
        <origin xyz="0.0625 -0.11 0" rpy="${pi/2} 0 0"/>
        <axis xyz="0 0 -1"/>
    </joint>    
    <link name="right_wheel_front">
        <visual>
            <geometry>
                <cylinder radius="0.05" length="0.02"/>
            </geometry>
            <material name="blue"/>
        </visual>
        <collision>
            <geometry>
                <cylinder radius="0.05" length="0.02"/>
            </geometry>
        </collision>
        <xacro:inertial_cylinder mass="0.1" length="0.02" radius="0.05">
            <origin xyz="0 0 0" rpy="0 0 0"/>
        </xacro:inertial_cylinder>
    </link>

    <gazebo reference="right_wheel_front">
        <material>Gazebo/Blue</material>
    </gazebo>

    <!--RIGHT REAR WHEEL-->

    <joint name="right_rear" type="continuous">
        <parent link="base_link"/>
        <child link="right_wheel_rear"/>
        <origin xyz="-0.0625 -0.11 0" rpy="${pi/2} 0 0"/>
        <axis xyz="0 0 -1"/>
    </joint>
    <link name="right_wheel_rear">
        <visual>
            <geometry>
                <cylinder radius="0.05" length="0.02"/>
            </geometry>
            <material name="black"/>
        </visual>
        <collision>
            <geometry>
                <cylinder radius="0.05" length="0.02"/>
            </geometry>
        </collision>
        <xacro:inertial_cylinder mass="0.1" length="0.02" radius="0.05">
            <origin xyz="0 0 0" rpy="0 0 0"/>
        </xacro:inertial_cylinder>
    </link>

    <gazebo reference="right_wheel_rear">
        <material>Gazebo/Black</material>
    </gazebo>

</robot>